Traceback (most recent call last):
  File "<frozen runpy>", line 189, in _run_module_as_main
  File "<frozen runpy>", line 148, in _get_module_details
  File "<frozen runpy>", line 112, in _get_module_details
  File "/app/shivu/__init__.py", line 3, in <module>
    from pyrogram.client import Client 
    ^^^^^^^^^^^^^^^^^^^^^^^^^^^^^^^^^^
  File "/app/.venv/lib/python3.11/site-packages/pyrogram/__init__.py", line 39, in <module>
    from .client import Client
  File "/app/.venv/lib/python3.11/site-packages/pyrogram/client.py", line 52, in <module>
    from pyrogram.storage import FileStorage, MemoryStorage
  File "/app/.venv/lib/python3.11/site-packages/pyrogram/storage/__init__.py", line 19, in <module>
    from .file_storage import FileStorage
  File "/app/.venv/lib/python3.11/site-packages/pyrogram/storage/file_storage.py", line 21, in <module>
    import sqlite3
  File "/mise/installs/python/3.11.0/lib/python3.11/sqlite3/__init__.py", line 57, in <module>
    from sqlite3.dbapi2 import *
  File "/mise/installs/python/3.11.0/lib/python3.11/sqlite3/dbapi2.py", line 27, in <module>
    from _sqlite3 import *
ImportError: libsqlite3.so.0: cannot open shared object file: No such file or directory
Traceback (most recent call last):
  File "<frozen runpy>", line 189, in _run_module_as_main
  File "<frozen runpy>", line 148, in _get_module_details
  File "<frozen runpy>", line 112, in _get_module_details
  File "/app/shivu/__init__.py", line 3, in <module>
    from pyrogram.client import Client 
    ^^^^^^^^^^^^^^^^^^^^^^^^^^^^^^^^^^
  File "/app/.venv/lib/python3.11/site-packages/pyrogram/__init__.py", line 39, in <module>
    from .client import Client
  File "/app/.venv/lib/python3.11/site-packages/pyrogram/client.py", line 52, in <module>
    from pyrogram.storage import FileStorage, MemoryStorage
  File "/app/.venv/lib/python3.11/site-packages/pyrogram/storage/__init__.py", line 19, in <module>
    from .file_storage import FileStorage
  File "/app/.venv/lib/python3.11/site-packages/pyrogram/storage/file_storage.py", line 21, in <module>
    import sqlite3
  File "/mise/installs/python/3.11.0/lib/python3.11/sqlite3/__init__.py", line 57, in <module>
    from sqlite3.dbapi2 import *
  File "/mise/installs/python/3.11.0/lib/python3.11/sqlite3/dbapi2.py", line 27, in <module>
    from _sqlite3 import *
ImportError: libsqlite3.so.0: cannot open shared object file: No such file or directory
Traceback (most recent call last):
  File "<frozen runpy>", line 189, in _run_module_as_main
  File "<frozen runpy>", line 148, in _get_module_details
  File "<frozen runpy>", line 112, in _get_module_details
  File "/app/shivu/__init__.py", line 3, in <module>
    from pyrogram.client import Client 
    ^^^^^^^^^^^^^^^^^^^^^^^^^^^^^^^^^^
  File "/app/.venv/lib/python3.11/site-packages/pyrogram/__init__.py", line 39, in <module>
    from .client import Client
  File "/app/.venv/lib/python3.11/site-packages/pyrogram/client.py", line 52, in <module>
    from pyrogram.storage import FileStorage, MemoryStorage
  File "/app/.venv/lib/python3.11/site-packages/pyrogram/storage/__init__.py", line 19, in <module>
    from .file_storage import FileStorage
  File "/app/.venv/lib/python3.11/site-packages/pyrogram/storage/file_storage.py", line 21, in <module>
    import sqlite3
  File "/mise/installs/python/3.11.0/lib/python3.11/sqlite3/__init__.py", line 57, in <module>
    from sqlite3.dbapi2 import *
  File "/mise/installs/python/3.11.0/lib/python3.11/sqlite3/dbapi2.py", line 27, in <module>
    from _sqlite3 import *
ImportError: libsqlite3.so.0: cannot open shared object file: No such file or directory